Workbook

Sheet TongQuan
A1: SỔ THU CHI - TỔNG QUAN
A3: Năm | B3: 2026 | C3: ← chọn năm / tháng cần xem
A4: Tháng | B4: 10
A6: Từ ngày | B6: =DATE(B3,B4,1) -> 46296
A7: Đến trước ngày | B7: =EDATE(B6,1) -> 46327
A9: TỔNG QUAN THÁNG ĐANG XEM | E9: ="THU CHI THEO THÁNG - NĂM "&B3 -> THU CHI THEO THÁNG - NĂM 2026
A10: Tổng tài sản (tất cả tài khoản) | B10: =TaiKhoan!I22 -> 0 | E10: Tháng | F10: Thu (₫) | G10: Chi (₫) | H10: Chênh lệch (₫)
A11: Thu trong tháng | B11: =SUMIFS(GiaoDich!$D:$D,GiaoDich!$C:$C,"Thu",GiaoDich!$B:$B,">="&$B$6,GiaoDich!$B:$B,"<"&$B$7) -> 0 | E11: 1 | F11: =SUMIFS(GiaoDich!$D:$D,GiaoDich!$C:$C,"Thu",GiaoDich!$B:$B,">="&DATE($B$3,$E11,1),GiaoDich!$B:$B,"<"&DATE($B$3,$E11+1,1)) -> 0 | G11: =SUMIFS(GiaoDich!$D:$D,GiaoDich!$C:$C,"Chi",GiaoDich!$B:$B,">="&DATE($B$3,$E11,1),GiaoDich!$B:$B,"<"&DATE($B$3,$E11+1,1)) -> 0 | H11: =F11-G11 -> 0
A12: Chi trong tháng | B12: =SUMIFS(GiaoDich!$D:$D,GiaoDich!$C:$C,"Chi",GiaoDich!$B:$B,">="&$B$6,GiaoDich!$B:$B,"<"&$B$7) -> 0 | E12: 2 | F12: =SUMIFS(GiaoDich!$D:$D,GiaoDich!$C:$C,"Thu",GiaoDich!$B:$B,">="&DATE($B$3,$E12,1),GiaoDich!$B:$B,"<"&DATE($B$3,$E12+1,1)) -> 0 | G12: =SUMIFS(GiaoDich!$D:$D,GiaoDich!$C:$C,"Chi",GiaoDich!$B:$B,">="&DATE($B$3,$E12,1),GiaoDich!$B:$B,"<"&DATE($B$3,$E12+1,1)) -> 0 | H12: =F12-G12 -> 0
A13: Chênh lệch (Thu − Chi) | B13: =B11-B12 -> 0 | E13: 3 | F13: =SUMIFS(GiaoDich!$D:$D,GiaoDich!$C:$C,"Thu",GiaoDich!$B:$B,">="&DATE($B$3,$E13,1),GiaoDich!$B:$B,"<"&DATE($B$3,$E13+1,1)) -> 0 | G13: =SUMIFS(GiaoDich!$D:$D,GiaoDich!$C:$C,"Chi",GiaoDich!$B:$B,">="&DATE($B$3,$E13,1),GiaoDich!$B:$B,"<"&DATE($B$3,$E13+1,1)) -> 0 | H13: =F13-G13 -> 0
A14: Tỷ lệ tiết kiệm | B14: =IF(B11=0,0,B13/B11) -> 0 | E14: 4 | F14: =SUMIFS(GiaoDich!$D:$D,GiaoDich!$C:$C,"Thu",GiaoDich!$B:$B,">="&DATE($B$3,$E14,1),GiaoDich!$B:$B,"<"&DATE($B$3,$E14+1,1)) -> 0 | G14: =SUMIFS(GiaoDich!$D:$D,GiaoDich!$C:$C,"Chi",GiaoDich!$B:$B,">="&DATE($B$3,$E14,1),GiaoDich!$B:$B,"<"&DATE($B$3,$E14+1,1)) -> 0 | H14: =F14-G14 -> 0
A15: Điều chỉnh số dư (không tính thu/chi) | B15: =SUMIFS(GiaoDich!$D:$D,GiaoDich!$C:$C,"Điều chỉnh",GiaoDich!$B:$B,">="&$B$6,GiaoDich!$B:$B,"<"&$B$7) -> 0 | E15: 5 | F15: =SUMIFS(GiaoDich!$D:$D,GiaoDich!$C:$C,"Thu",GiaoDich!$B:$B,">="&DATE($B$3,$E15,1),GiaoDich!$B:$B,"<"&DATE($B$3,$E15+1,1)) -> 0 | G15: =SUMIFS(GiaoDich!$D:$D,GiaoDich!$C:$C,"Chi",GiaoDich!$B:$B,">="&DATE($B$3,$E15,1),GiaoDich!$B:$B,"<"&DATE($B$3,$E15+1,1)) -> 0 | H15: =F15-G15 -> 0
A16: Số giao dịch trong tháng | B16: =COUNTIFS(GiaoDich!$B:$B,">="&$B$6,GiaoDich!$B:$B,"<"&$B$7) -> 0 | E16: 6 | F16: =SUMIFS(GiaoDich!$D:$D,GiaoDich!$C:$C,"Thu",GiaoDich!$B:$B,">="&DATE($B$3,$E16,1),GiaoDich!$B:$B,"<"&DATE($B$3,$E16+1,1)) -> 0 | G16: =SUMIFS(GiaoDich!$D:$D,GiaoDich!$C:$C,"Chi",GiaoDich!$B:$B,">="&DATE($B$3,$E16,1),GiaoDich!$B:$B,"<"&DATE($B$3,$E16+1,1)) -> 0 | H16: =F16-G16 -> 0
E17: 7 | F17: =SUMIFS(GiaoDich!$D:$D,GiaoDich!$C:$C,"Thu",GiaoDich!$B:$B,">="&DATE($B$3,$E17,1),GiaoDich!$B:$B,"<"&DATE($B$3,$E17+1,1)) -> 0 | G17: =SUMIFS(GiaoDich!$D:$D,GiaoDich!$C:$C,"Chi",GiaoDich!$B:$B,">="&DATE($B$3,$E17,1),GiaoDich!$B:$B,"<"&DATE($B$3,$E17+1,1)) -> 0 | H17: =F17-G17 -> 0
A18: CHI THEO HẠNG MỤC CHA | E18: 8 | F18: =SUMIFS(GiaoDich!$D:$D,GiaoDich!$C:$C,"Thu",GiaoDich!$B:$B,">="&DATE($B$3,$E18,1),GiaoDich!$B:$B,"<"&DATE($B$3,$E18+1,1)) -> 0 | G18: =SUMIFS(GiaoDich!$D:$D,GiaoDich!$C:$C,"Chi",GiaoDich!$B:$B,">="&DATE($B$3,$E18,1),GiaoDich!$B:$B,"<"&DATE($B$3,$E18+1,1)) -> 0 | H18: =F18-G18 -> 0
A19: Hạng mục | B19: Số tiền (₫) | C19: Tỷ lệ | E19: 9 | F19: =SUMIFS(GiaoDich!$D:$D,GiaoDich!$C:$C,"Thu",GiaoDich!$B:$B,">="&DATE($B$3,$E19,1),GiaoDich!$B:$B,"<"&DATE($B$3,$E19+1,1)) -> 0 | G19: =SUMIFS(GiaoDich!$D:$D,GiaoDich!$C:$C,"Chi",GiaoDich!$B:$B,">="&DATE($B$3,$E19,1),GiaoDich!$B:$B,"<"&DATE($B$3,$E19+1,1)) -> 0 | H19: =F19-G19 -> 0
A20: =DanhMuc!E2 -> Ăn uống | B20: =SUMIFS(GiaoDich!$D:$D,GiaoDich!$C:$C,"Chi",GiaoDich!$G:$G,A20,GiaoDich!$B:$B,">="&$B$6,GiaoDich!$B:$B,"<"&$B$7) -> 0 | C20: =IF($B$12=0,0,B20/$B$12) -> 0 | E20: 10 | F20: =SUMIFS(GiaoDich!$D:$D,GiaoDich!$C:$C,"Thu",GiaoDich!$B:$B,">="&DATE($B$3,$E20,1),GiaoDich!$B:$B,"<"&DATE($B$3,$E20+1,1)) -> 0 | G20: =SUMIFS(GiaoDich!$D:$D,GiaoDich!$C:$C,"Chi",GiaoDich!$B:$B,">="&DATE($B$3,$E20,1),GiaoDich!$B:$B,"<"&DATE($B$3,$E20+1,1)) -> 0 | H20: =F20-G20 -> 0
A21: =DanhMuc!E3 -> Đi lại | B21: =SUMIFS(GiaoDich!$D:$D,GiaoDich!$C:$C,"Chi",GiaoDich!$G:$G,A21,GiaoDich!$B:$B,">="&$B$6,GiaoDich!$B:$B,"<"&$B$7) -> 0 | C21: =IF($B$12=0,0,B21/$B$12) -> 0 | E21: 11 | F21: =SUMIFS(GiaoDich!$D:$D,GiaoDich!$C:$C,"Thu",GiaoDich!$B:$B,">="&DATE($B$3,$E21,1),GiaoDich!$B:$B,"<"&DATE($B$3,$E21+1,1)) -> 0 | G21: =SUMIFS(GiaoDich!$D:$D,GiaoDich!$C:$C,"Chi",GiaoDich!$B:$B,">="&DATE($B$3,$E21,1),GiaoDich!$B:$B,"<"&DATE($B$3,$E21+1,1)) -> 0 | H21: =F21-G21 -> 0
A22: =DanhMuc!E4 -> Nhà cửa | B22: =SUMIFS(GiaoDich!$D:$D,GiaoDich!$C:$C,"Chi",GiaoDich!$G:$G,A22,GiaoDich!$B:$B,">="&$B$6,GiaoDich!$B:$B,"<"&$B$7) -> 0 | C22: =IF($B$12=0,0,B22/$B$12) -> 0 | E22: 12 | F22: =SUMIFS(GiaoDich!$D:$D,GiaoDich!$C:$C,"Thu",GiaoDich!$B:$B,">="&DATE($B$3,$E22,1),GiaoDich!$B:$B,"<"&DATE($B$3,$E22+1,1)) -> 0 | G22: =SUMIFS(GiaoDich!$D:$D,GiaoDich!$C:$C,"Chi",GiaoDich!$B:$B,">="&DATE($B$3,$E22,1),GiaoDich!$B:$B,"<"&DATE($B$3,$E22+1,1)) -> 0 | H22: =F22-G22 -> 0
A23: =DanhMuc!E5 -> Gia đình | B23: =SUMIFS(GiaoDich!$D:$D,GiaoDich!$C:$C,"Chi",GiaoDich!$G:$G,A23,GiaoDich!$B:$B,">="&$B$6,GiaoDich!$B:$B,"<"&$B$7) -> 0 | C23: =IF($B$12=0,0,B23/$B$12) -> 0 | E23: Cả năm | F23: =SUM(F11:F22) -> 0 | G23: =SUM(G11:G22) -> 0 | H23: =SUM(H11:H22) -> 0
A24: =DanhMuc!E6 -> Hiếu hỉ | B24: =SUMIFS(GiaoDich!$D:$D,GiaoDich!$C:$C,"Chi",GiaoDich!$G:$G,A24,GiaoDich!$B:$B,">="&$B$6,GiaoDich!$B:$B,"<"&$B$7) -> 0 | C24: =IF($B$12=0,0,B24/$B$12) -> 0
A25: =DanhMuc!E7 -> Học tập | B25: =SUMIFS(GiaoDich!$D:$D,GiaoDich!$C:$C,"Chi",GiaoDich!$G:$G,A25,GiaoDich!$B:$B,">="&$B$6,GiaoDich!$B:$B,"<"&$B$7) -> 0 | C25: =IF($B$12=0,0,B25/$B$12) -> 0
A26: =DanhMuc!E8 -> Giải trí | B26: =SUMIFS(GiaoDich!$D:$D,GiaoDich!$C:$C,"Chi",GiaoDich!$G:$G,A26,GiaoDich!$B:$B,">="&$B$6,GiaoDich!$B:$B,"<"&$B$7) -> 0 | C26: =IF($B$12=0,0,B26/$B$12) -> 0
A27: =DanhMuc!E9 -> Mua sắm | B27: =SUMIFS(GiaoDich!$D:$D,GiaoDich!$C:$C,"Chi",GiaoDich!$G:$G,A27,GiaoDich!$B:$B,">="&$B$6,GiaoDich!$B:$B,"<"&$B$7) -> 0 | C27: =IF($B$12=0,0,B27/$B$12) -> 0
A28: =DanhMuc!E10 -> Sức khỏe | B28: =SUMIFS(GiaoDich!$D:$D,GiaoDich!$C:$C,"Chi",GiaoDich!$G:$G,A28,GiaoDich!$B:$B,">="&$B$6,GiaoDich!$B:$B,"<"&$B$7) -> 0 | C28: =IF($B$12=0,0,B28/$B$12) -> 0
A29: =DanhMuc!E11 -> Liên lạc | B29: =SUMIFS(GiaoDich!$D:$D,GiaoDich!$C:$C,"Chi",GiaoDich!$G:$G,A29,GiaoDich!$B:$B,">="&$B$6,GiaoDich!$B:$B,"<"&$B$7) -> 0 | C29: =IF($B$12=0,0,B29/$B$12) -> 0
A30: =DanhMuc!E12 -> Tài chính | B30: =SUMIFS(GiaoDich!$D:$D,GiaoDich!$C:$C,"Chi",GiaoDich!$G:$G,A30,GiaoDich!$B:$B,">="&$B$6,GiaoDich!$B:$B,"<"&$B$7) -> 0 | C30: =IF($B$12=0,0,B30/$B$12) -> 0
A31: =DanhMuc!E13 -> Trả nợ | B31: =SUMIFS(GiaoDich!$D:$D,GiaoDich!$C:$C,"Chi",GiaoDich!$G:$G,A31,GiaoDich!$B:$B,">="&$B$6,GiaoDich!$B:$B,"<"&$B$7) -> 0 | C31: =IF($B$12=0,0,B31/$B$12) -> 0
A32: =DanhMuc!E14 -> Khác | B32: =SUMIFS(GiaoDich!$D:$D,GiaoDich!$C:$C,"Chi",GiaoDich!$G:$G,A32,GiaoDich!$B:$B,">="&$B$6,GiaoDich!$B:$B,"<"&$B$7) -> 0 | C32: =IF($B$12=0,0,B32/$B$12) -> 0
A33: Chưa phân loại | B33: =$B$12-SUM(B20:B32) -> 0 | C33: =IF($B$12=0,0,B33/$B$12) -> 0
A34: Tổng chi | B34: =SUM(B20:B33) -> 0 | C34: =IF($B$12=0,0,B34/$B$12) -> 0
A36: THU THEO NGUỒN
A37: Hạng mục | B37: Số tiền (₫) | C37: Tỷ lệ
A38: =DanhMuc!E15 -> Lương | B38: =SUMIFS(GiaoDich!$D:$D,GiaoDich!$C:$C,"Thu",GiaoDich!$G:$G,A38,GiaoDich!$B:$B,">="&$B$6,GiaoDich!$B:$B,"<"&$B$7) -> 0 | C38: =IF($B$11=0,0,B38/$B$11) -> 0
A39: =DanhMuc!E16 -> Thưởng | B39: =SUMIFS(GiaoDich!$D:$D,GiaoDich!$C:$C,"Thu",GiaoDich!$G:$G,A39,GiaoDich!$B:$B,">="&$B$6,GiaoDich!$B:$B,"<"&$B$7) -> 0 | C39: =IF($B$11=0,0,B39/$B$11) -> 0
A40: =DanhMuc!E17 -> Làm thêm | B40: =SUMIFS(GiaoDich!$D:$D,GiaoDich!$C:$C,"Thu",GiaoDich!$G:$G,A40,GiaoDich!$B:$B,">="&$B$6,GiaoDich!$B:$B,"<"&$B$7) -> 0 | C40: =IF($B$11=0,0,B40/$B$11) -> 0
A41: =DanhMuc!E18 -> Đầu tư & lãi | B41: =SUMIFS(GiaoDich!$D:$D,GiaoDich!$C:$C,"Thu",GiaoDich!$G:$G,A41,GiaoDich!$B:$B,">="&$B$6,GiaoDich!$B:$B,"<"&$B$7) -> 0 | C41: =IF($B$11=0,0,B41/$B$11) -> 0
A42: =DanhMuc!E19 -> Quà tặng | B42: =SUMIFS(GiaoDich!$D:$D,GiaoDich!$C:$C,"Thu",GiaoDich!$G:$G,A42,GiaoDich!$B:$B,">="&$B$6,GiaoDich!$B:$B,"<"&$B$7) -> 0 | C42: =IF($B$11=0,0,B42/$B$11) -> 0
A43: =DanhMuc!E20 -> Thu khác | B43: =SUMIFS(GiaoDich!$D:$D,GiaoDich!$C:$C,"Thu",GiaoDich!$G:$G,A43,GiaoDich!$B:$B,">="&$B$6,GiaoDich!$B:$B,"<"&$B$7) -> 0 | C43: =IF($B$11=0,0,B43/$B$11) -> 0
A44: Chưa phân loại | B44: =$B$11-SUM(B38:B43) -> 0 | C44: =IF($B$11=0,0,B44/$B$11) -> 0
...

Sheet GiaoDich
A1: ID | B1: Ngày | C1: Loại | D1: Số tiền (₫) | E1: Tài khoản | F1: Tài khoản đến (chỉ khi Chuyển khoản) | G1: Hạng mục cha | H1: Hạng mục con | I1: Ghi chú | J1: Tạo lúc

Sheet TaiKhoan
A1: Tên tài khoản | B1: Loại | C1: Số dư đầu kỳ | D1: Thu | E1: Chi | F1: Chuyển vào | G1: Chuyển ra | H1: Điều chỉnh | I1: Số dư hiện tại | J1: Ghi chú
A2: Tiền mặt | B2: Tiền mặt | C2: 0 | D2: =IF($A2="","",SUMIFS(GiaoDich!$D:$D,GiaoDich!$C:$C,"Thu",GiaoDich!$E:$E,$A2)) -> 0 | E2: =IF($A2="","",SUMIFS(GiaoDich!$D:$D,GiaoDich!$C:$C,"Chi",GiaoDich!$E:$E,$A2)) -> 0 | F2: =IF($A2="","",SUMIFS(GiaoDich!$D:$D,GiaoDich!$C:$C,"Chuyển khoản",GiaoDich!$F:$F,$A2)) -> 0 | G2: =IF($A2="","",SUMIFS(GiaoDich!$D:$D,GiaoDich!$C:$C,"Chuyển khoản",GiaoDich!$E:$E,$A2)) -> 0 | H2: =IF($A2="","",SUMIFS(GiaoDich!$D:$D,GiaoDich!$C:$C,"Điều chỉnh",GiaoDich!$E:$E,$A2)) -> 0 | I2: =IF($A2="","",C2+D2-E2+F2-G2+H2) -> 0
A3: Ngân hàng chính | B3: Ngân hàng | C3: 0 | D3: =IF($A3="","",SUMIFS(GiaoDich!$D:$D,GiaoDich!$C:$C,"Thu",GiaoDich!$E:$E,$A3)) -> 0 | E3: =IF($A3="","",SUMIFS(GiaoDich!$D:$D,GiaoDich!$C:$C,"Chi",GiaoDich!$E:$E,$A3)) -> 0 | F3: =IF($A3="","",SUMIFS(GiaoDich!$D:$D,GiaoDich!$C:$C,"Chuyển khoản",GiaoDich!$F:$F,$A3)) -> 0 | G3: =IF($A3="","",SUMIFS(GiaoDich!$D:$D,GiaoDich!$C:$C,"Chuyển khoản",GiaoDich!$E:$E,$A3)) -> 0 | H3: =IF($A3="","",SUMIFS(GiaoDich!$D:$D,GiaoDich!$C:$C,"Điều chỉnh",GiaoDich!$E:$E,$A3)) -> 0 | I3: =IF($A3="","",C3+D3-E3+F3-G3+H3) -> 0
A4: Ví điện tử | B4: Ví điện tử | C4: 0 | D4: =IF($A4="","",SUMIFS(GiaoDich!$D:$D,GiaoDich!$C:$C,"Thu",GiaoDich!$E:$E,$A4)) -> 0 | E4: =IF($A4="","",SUMIFS(GiaoDich!$D:$D,GiaoDich!$C:$C,"Chi",GiaoDich!$E:$E,$A4)) -> 0 | F4: =IF($A4="","",SUMIFS(GiaoDich!$D:$D,GiaoDich!$C:$C,"Chuyển khoản",GiaoDich!$F:$F,$A4)) -> 0 | G4: =IF($A4="","",SUMIFS(GiaoDich!$D:$D,GiaoDich!$C:$C,"Chuyển khoản",GiaoDich!$E:$E,$A4)) -> 0 | H4: =IF($A4="","",SUMIFS(GiaoDich!$D:$D,GiaoDich!$C:$C,"Điều chỉnh",GiaoDich!$E:$E,$A4)) -> 0 | I4: =IF($A4="","",C4+D4-E4+F4-G4+H4) -> 0
A5: Tiết kiệm | B5: Tiết kiệm | C5: 0 | D5: =IF($A5="","",SUMIFS(GiaoDich!$D:$D,GiaoDich!$C:$C,"Thu",GiaoDich!$E:$E,$A5)) -> 0 | E5: =IF($A5="","",SUMIFS(GiaoDich!$D:$D,GiaoDich!$C:$C,"Chi",GiaoDich!$E:$E,$A5)) -> 0 | F5: =IF($A5="","",SUMIFS(GiaoDich!$D:$D,GiaoDich!$C:$C,"Chuyển khoản",GiaoDich!$F:$F,$A5)) -> 0 | G5: =IF($A5="","",SUMIFS(GiaoDich!$D:$D,GiaoDich!$C:$C,"Chuyển khoản",GiaoDich!$E:$E,$A5)) -> 0 | H5: =IF($A5="","",SUMIFS(GiaoDich!$D:$D,GiaoDich!$C:$C,"Điều chỉnh",GiaoDich!$E:$E,$A5)) -> 0 | I5: =IF($A5="","",C5+D5-E5+F5-G5+H5) -> 0
D6: =IF($A6="","",SUMIFS(GiaoDich!$D:$D,GiaoDich!$C:$C,"Thu",GiaoDich!$E:$E,$A6)) | E6: =IF($A6="","",SUMIFS(GiaoDich!$D:$D,GiaoDich!$C:$C,"Chi",GiaoDich!$E:$E,$A6)) | F6: =IF($A6="","",SUMIFS(GiaoDich!$D:$D,GiaoDich!$C:$C,"Chuyển khoản",GiaoDich!$F:$F,$A6)) | G6: =IF($A6="","",SUMIFS(GiaoDich!$D:$D,GiaoDich!$C:$C,"Chuyển khoản",GiaoDich!$E:$E,$A6)) | H6: =IF($A6="","",SUMIFS(GiaoDich!$D:$D,GiaoDich!$C:$C,"Điều chỉnh",GiaoDich!$E:$E,$A6)) | I6: =IF($A6="","",C6+D6-E6+F6-G6+H6)
D7: =IF($A7="","",SUMIFS(GiaoDich!$D:$D,GiaoDich!$C:$C,"Thu",GiaoDich!$E:$E,$A7)) | E7: =IF($A7="","",SUMIFS(GiaoDich!$D:$D,GiaoDich!$C:$C,"Chi",GiaoDich!$E:$E,$A7)) | F7: =IF($A7="","",SUMIFS(GiaoDich!$D:$D,GiaoDich!$C:$C,"Chuyển khoản",GiaoDich!$F:$F,$A7)) | G7: =IF($A7="","",SUMIFS(GiaoDich!$D:$D,GiaoDich!$C:$C,"Chuyển khoản",GiaoDich!$E:$E,$A7)) | H7: =IF($A7="","",SUMIFS(GiaoDich!$D:$D,GiaoDich!$C:$C,"Điều chỉnh",GiaoDich!$E:$E,$A7)) | I7: =IF($A7="","",C7+D7-E7+F7-G7+H7)
D8: =IF($A8="","",SUMIFS(GiaoDich!$D:$D,GiaoDich!$C:$C,"Thu",GiaoDich!$E:$E,$A8)) | E8: =IF($A8="","",SUMIFS(GiaoDich!$D:$D,GiaoDich!$C:$C,"Chi",GiaoDich!$E:$E,$A8)) | F8: =IF($A8="","",SUMIFS(GiaoDich!$D:$D,GiaoDich!$C:$C,"Chuyển khoản",GiaoDich!$F:$F,$A8)) | G8: =IF($A8="","",SUMIFS(GiaoDich!$D:$D,GiaoDich!$C:$C,"Chuyển khoản",GiaoDich!$E:$E,$A8)) | H8: =IF($A8="","",SUMIFS(GiaoDich!$D:$D,GiaoDich!$C:$C,"Điều chỉnh",GiaoDich!$E:$E,$A8)) | I8: =IF($A8="","",C8+D8-E8+F8-G8+H8)
D9: =IF($A9="","",SUMIFS(GiaoDich!$D:$D,GiaoDich!$C:$C,"Thu",GiaoDich!$E:$E,$A9)) | E9: =IF($A9="","",SUMIFS(GiaoDich!$D:$D,GiaoDich!$C:$C,"Chi",GiaoDich!$E:$E,$A9)) | F9: =IF($A9="","",SUMIFS(GiaoDich!$D:$D,GiaoDich!$C:$C,"Chuyển khoản",GiaoDich!$F:$F,$A9)) | G9: =IF($A9="","",SUMIFS(GiaoDich!$D:$D,GiaoDich!$C:$C,"Chuyển khoản",GiaoDich!$E:$E,$A9)) | H9: =IF($A9="","",SUMIFS(GiaoDich!$D:$D,GiaoDich!$C:$C,"Điều chỉnh",GiaoDich!$E:$E,$A9)) | I9: =IF($A9="","",C9+D9-E9+F9-G9+H9)
D10: =IF($A10="","",SUMIFS(GiaoDich!$D:$D,GiaoDich!$C:$C,"Thu",GiaoDich!$E:$E,$A10)) | E10: =IF($A10="","",SUMIFS(GiaoDich!$D:$D,GiaoDich!$C:$C,"Chi",GiaoDich!$E:$E,$A10)) | F10: =IF($A10="","",SUMIFS(GiaoDich!$D:$D,GiaoDich!$C:$C,"Chuyển khoản",GiaoDich!$F:$F,$A10)) | G10: =IF($A10="","",SUMIFS(GiaoDich!$D:$D,GiaoDich!$C:$C,"Chuyển khoản",GiaoDich!$E:$E,$A10)) | H10: =IF($A10="","",SUMIFS(GiaoDich!$D:$D,GiaoDich!$C:$C,"Điều chỉnh",GiaoDich!$E:$E,$A10)) | I10: =IF($A10="","",C10+D10-E10+F10-G10+H10)
D11: =IF($A11="","",SUMIFS(GiaoDich!$D:$D,GiaoDich!$C:$C,"Thu",GiaoDich!$E:$E,$A11)) | E11: =IF($A11="","",SUMIFS(GiaoDich!$D:$D,GiaoDich!$C:$C,"Chi",GiaoDich!$E:$E,$A11)) | F11: =IF($A11="","",SUMIFS(GiaoDich!$D:$D,GiaoDich!$C:$C,"Chuyển khoản",GiaoDich!$F:$F,$A11)) | G11: =IF($A11="","",SUMIFS(GiaoDich!$D:$D,GiaoDich!$C:$C,"Chuyển khoản",GiaoDich!$E:$E,$A11)) | H11: =IF($A11="","",SUMIFS(GiaoDich!$D:$D,GiaoDich!$C:$C,"Điều chỉnh",GiaoDich!$E:$E,$A11)) | I11: =IF($A11="","",C11+D11-E11+F11-G11+H11)
D12: =IF($A12="","",SUMIFS(GiaoDich!$D:$D,GiaoDich!$C:$C,"Thu",GiaoDich!$E:$E,$A12)) | E12: =IF($A12="","",SUMIFS(GiaoDich!$D:$D,GiaoDich!$C:$C,"Chi",GiaoDich!$E:$E,$A12)) | F12: =IF($A12="","",SUMIFS(GiaoDich!$D:$D,GiaoDich!$C:$C,"Chuyển khoản",GiaoDich!$F:$F,$A12)) | G12: =IF($A12="","",SUMIFS(GiaoDich!$D:$D,GiaoDich!$C:$C,"Chuyển khoản",GiaoDich!$E:$E,$A12)) | H12: =IF($A12="","",SUMIFS(GiaoDich!$D:$D,GiaoDich!$C:$C,"Điều chỉnh",GiaoDich!$E:$E,$A12)) | I12: =IF($A12="","",C12+D12-E12+F12-G12+H12)
D13: =IF($A13="","",SUMIFS(GiaoDich!$D:$D,GiaoDich!$C:$C,"Thu",GiaoDich!$E:$E,$A13)) | E13: =IF($A13="","",SUMIFS(GiaoDich!$D:$D,GiaoDich!$C:$C,"Chi",GiaoDich!$E:$E,$A13)) | F13: =IF($A13="","",SUMIFS(GiaoDich!$D:$D,GiaoDich!$C:$C,"Chuyển khoản",GiaoDich!$F:$F,$A13)) | G13: =IF($A13="","",SUMIFS(GiaoDich!$D:$D,GiaoDich!$C:$C,"Chuyển khoản",GiaoDich!$E:$E,$A13)) | H13: =IF($A13="","",SUMIFS(GiaoDich!$D:$D,GiaoDich!$C:$C,"Điều chỉnh",GiaoDich!$E:$E,$A13)) | I13: =IF($A13="","",C13+D13-E13+F13-G13+H13)
D14: =IF($A14="","",SUMIFS(GiaoDich!$D:$D,GiaoDich!$C:$C,"Thu",GiaoDich!$E:$E,$A14)) | E14: =IF($A14="","",SUMIFS(GiaoDich!$D:$D,GiaoDich!$C:$C,"Chi",GiaoDich!$E:$E,$A14)) | F14: =IF($A14="","",SUMIFS(GiaoDich!$D:$D,GiaoDich!$C:$C,"Chuyển khoản",GiaoDich!$F:$F,$A14)) | G14: =IF($A14="","",SUMIFS(GiaoDich!$D:$D,GiaoDich!$C:$C,"Chuyển khoản",GiaoDich!$E:$E,$A14)) | H14: =IF($A14="","",SUMIFS(GiaoDich!$D:$D,GiaoDich!$C:$C,"Điều chỉnh",GiaoDich!$E:$E,$A14)) | I14: =IF($A14="","",C14+D14-E14+F14-G14+H14)
D15: =IF($A15="","",SUMIFS(GiaoDich!$D:$D,GiaoDich!$C:$C,"Thu",GiaoDich!$E:$E,$A15)) | E15: =IF($A15="","",SUMIFS(GiaoDich!$D:$D,GiaoDich!$C:$C,"Chi",GiaoDich!$E:$E,$A15)) | F15: =IF($A15="","",SUMIFS(GiaoDich!$D:$D,GiaoDich!$C:$C,"Chuyển khoản",GiaoDich!$F:$F,$A15)) | G15: =IF($A15="","",SUMIFS(GiaoDich!$D:$D,GiaoDich!$C:$C,"Chuyển khoản",GiaoDich!$E:$E,$A15)) | H15: =IF($A15="","",SUMIFS(GiaoDich!$D:$D,GiaoDich!$C:$C,"Điều chỉnh",GiaoDich!$E:$E,$A15)) | I15: =IF($A15="","",C15+D15-E15+F15-G15+H15)
D16: =IF($A16="","",SUMIFS(GiaoDich!$D:$D,GiaoDich!$C:$C,"Thu",GiaoDich!$E:$E,$A16)) | E16: =IF($A16="","",SUMIFS(GiaoDich!$D:$D,GiaoDich!$C:$C,"Chi",GiaoDich!$E:$E,$A16)) | F16: =IF($A16="","",SUMIFS(GiaoDich!$D:$D,GiaoDich!$C:$C,"Chuyển khoản",GiaoDich!$F:$F,$A16)) | G16: =IF($A16="","",SUMIFS(GiaoDich!$D:$D,GiaoDich!$C:$C,"Chuyển khoản",GiaoDich!$E:$E,$A16)) | H16: =IF($A16="","",SUMIFS(GiaoDich!$D:$D,GiaoDich!$C:$C,"Điều chỉnh",GiaoDich!$E:$E,$A16)) | I16: =IF($A16="","",C16+D16-E16+F16-G16+H16)
D17: =IF($A17="","",SUMIFS(GiaoDich!$D:$D,GiaoDich!$C:$C,"Thu",GiaoDich!$E:$E,$A17)) | E17: =IF($A17="","",SUMIFS(GiaoDich!$D:$D,GiaoDich!$C:$C,"Chi",GiaoDich!$E:$E,$A17)) | F17: =IF($A17="","",SUMIFS(GiaoDich!$D:$D,GiaoDich!$C:$C,"Chuyển khoản",GiaoDich!$F:$F,$A17)) | G17: =IF($A17="","",SUMIFS(GiaoDich!$D:$D,GiaoDich!$C:$C,"Chuyển khoản",GiaoDich!$E:$E,$A17)) | H17: =IF($A17="","",SUMIFS(GiaoDich!$D:$D,GiaoDich!$C:$C,"Điều chỉnh",GiaoDich!$E:$E,$A17)) | I17: =IF($A17="","",C17+D17-E17+F17-G17+H17)
... D21: =IF($A21="","",SUMIFS(GiaoDich!$D:$D,GiaoDich!$C:$C,"Thu",GiaoDich!$E:$E,$A21)) | E21: =IF($A21="","",SUMIFS(GiaoDich!$D:$D,GiaoDich!$C:$C,"Chi",GiaoDich!$E:$E,$A21)) | F21: =IF($A21="","",SUMIFS(GiaoDich!$D:$D,GiaoDich!$C:$C,"Chuyển khoản",GiaoDich!$F:$F,$A21)) | G21: =IF($A21="","",SUMIFS(GiaoDich!$D:$D,GiaoDich!$C:$C,"Chuyển khoản",GiaoDich!$E:$E,$A21)) | H21: =IF($A21="","",SUMIFS(GiaoDich!$D:$D,GiaoDich!$C:$C,"Điều chỉnh",GiaoDich!$E:$E,$A21)) | I21: =IF($A21="","",C21+D21-E21+F21-G21+H21)
A22: TỔNG | C22: =SUM(C2:C21) -> 0 | D22: =SUM(D2:D21) -> 0 | E22: =SUM(E2:E21) -> 0 | F22: =SUM(F2:F21) -> 0 | G22: =SUM(G2:G21) -> 0 | H22: =SUM(H2:H21) -> 0 | I22: =SUM(I2:I21) -> 0
A24: Số dư hiện tại = Số dư đầu kỳ + Thu − Chi + Chuyển vào − Chuyển ra + Điều chỉnh. Thẻ tín dụng: để số dư đầu kỳ âm nếu đang nợ.

Sheet DanhMuc
A1: Loại | B1: Hạng mục cha | C1: Hạng mục con | D1: Số tiền tháng đang xem (₫) | E1: Hạng mục cha (tất cả) | F1: Loại | H1: Loại giao dịch | J1: Thêm/sửa hạng mục: sửa cột A-C (mỗi hạng mục con phải có tên riêng, không trùng). Thêm hạng mục cha mới ở cột E-F.
A2: Chi | B2: Ăn uống | C2: Ăn sáng | D2: =IF(C2="","",SUMIFS(GiaoDich!$D:$D,GiaoDich!$C:$C,A2,GiaoDich!$H:$H,C2,GiaoDich!$B:$B,">="&TongQuan!$B$6,GiaoDich!$B:$B,"<"&TongQuan!$B$7)) -> 0 | E2: Ăn uống | F2: Chi | H2: Thu
A3: Chi | B3: Ăn uống | C3: Ăn trưa | D3: =IF(C3="","",SUMIFS(GiaoDich!$D:$D,GiaoDich!$C:$C,A3,GiaoDich!$H:$H,C3,GiaoDich!$B:$B,">="&TongQuan!$B$6,GiaoDich!$B:$B,"<"&TongQuan!$B$7)) -> 0 | E3: Đi lại | F3: Chi | H3: Chi
A4: Chi | B4: Ăn uống | C4: Ăn tối | D4: =IF(C4="","",SUMIFS(GiaoDich!$D:$D,GiaoDich!$C:$C,A4,GiaoDich!$H:$H,C4,GiaoDich!$B:$B,">="&TongQuan!$B$6,GiaoDich!$B:$B,"<"&TongQuan!$B$7)) -> 0 | E4: Nhà cửa | F4: Chi | H4: Chuyển khoản
A5: Chi | B5: Ăn uống | C5: Đi chợ/siêu thị | D5: =IF(C5="","",SUMIFS(GiaoDich!$D:$D,GiaoDich!$C:$C,A5,GiaoDich!$H:$H,C5,GiaoDich!$B:$B,">="&TongQuan!$B$6,GiaoDich!$B:$B,"<"&TongQuan!$B$7)) -> 0 | E5: Gia đình | F5: Chi | H5: Điều chỉnh
A6: Chi | B6: Ăn uống | C6: Cafe, trà sữa | D6: =IF(C6="","",SUMIFS(GiaoDich!$D:$D,GiaoDich!$C:$C,A6,GiaoDich!$H:$H,C6,GiaoDich!$B:$B,">="&TongQuan!$B$6,GiaoDich!$B:$B,"<"&TongQuan!$B$7)) -> 0 | E6: Hiếu hỉ | F6: Chi
A7: Chi | B7: Ăn uống | C7: Ăn vặt | D7: =IF(C7="","",SUMIFS(GiaoDich!$D:$D,GiaoDich!$C:$C,A7,GiaoDich!$H:$H,C7,GiaoDich!$B:$B,">="&TongQuan!$B$6,GiaoDich!$B:$B,"<"&TongQuan!$B$7)) -> 0 | E7: Học tập | F7: Chi
A8: Chi | B8: Đi lại | C8: Gửi xe | D8: =IF(C8="","",SUMIFS(GiaoDich!$D:$D,GiaoDich!$C:$C,A8,GiaoDich!$H:$H,C8,GiaoDich!$B:$B,">="&TongQuan!$B$6,GiaoDich!$B:$B,"<"&TongQuan!$B$7)) -> 0 | E8: Giải trí | F8: Chi
A9: Chi | B9: Đi lại | C9: Xăng xe | D9: =IF(C9="","",SUMIFS(GiaoDich!$D:$D,GiaoDich!$C:$C,A9,GiaoDich!$H:$H,C9,GiaoDich!$B:$B,">="&TongQuan!$B$6,GiaoDich!$B:$B,"<"&TongQuan!$B$7)) -> 0 | E9: Mua sắm | F9: Chi
A10: Chi | B10: Đi lại | C10: Sửa chữa, bảo dưỡng xe | D10: =IF(C10="","",SUMIFS(GiaoDich!$D:$D,GiaoDich!$C:$C,A10,GiaoDich!$H:$H,C10,GiaoDich!$B:$B,">="&TongQuan!$B$6,GiaoDich!$B:$B,"<"&TongQuan!$B$7)) -> 0 | E10: Sức khỏe | F10: Chi
A11: Chi | B11: Đi lại | C11: Taxi/Grab/xe buýt | D11: =IF(C11="","",SUMIFS(GiaoDich!$D:$D,GiaoDich!$C:$C,A11,GiaoDich!$H:$H,C11,GiaoDich!$B:$B,">="&TongQuan!$B$6,GiaoDich!$B:$B,"<"&TongQuan!$B$7)) -> 0 | E11: Liên lạc | F11: Chi
A12: Chi | B12: Đi lại | C12: Vé tàu, xe, máy bay | D12: =IF(C12="","",SUMIFS(GiaoDich!$D:$D,GiaoDich!$C:$C,A12,GiaoDich!$H:$H,C12,GiaoDich!$B:$B,">="&TongQuan!$B$6,GiaoDich!$B:$B,"<"&TongQuan!$B$7)) -> 0 | E12: Tài chính | F12: Chi
A13: Chi | B13: Đi lại | C13: Phí cầu đường | D13: =IF(C13="","",SUMIFS(GiaoDich!$D:$D,GiaoDich!$C:$C,A13,GiaoDich!$H:$H,C13,GiaoDich!$B:$B,">="&TongQuan!$B$6,GiaoDich!$B:$B,"<"&TongQuan!$B$7)) -> 0 | E13: Trả nợ | F13: Chi
A14: Chi | B14: Đi lại | C14: Bảo hiểm, đăng kiểm xe | D14: =IF(C14="","",SUMIFS(GiaoDich!$D:$D,GiaoDich!$C:$C,A14,GiaoDich!$H:$H,C14,GiaoDich!$B:$B,">="&TongQuan!$B$6,GiaoDich!$B:$B,"<"&TongQuan!$B$7)) -> 0 | E14: Khác | F14: Chi
A15: Chi | B15: Nhà cửa | C15: Thuê nhà | D15: =IF(C15="","",SUMIFS(GiaoDich!$D:$D,GiaoDich!$C:$C,A15,GiaoDich!$H:$H,C15,GiaoDich!$B:$B,">="&TongQuan!$B$6,GiaoDich!$B:$B,"<"&TongQuan!$B$7)) -> 0 | E15: Lương | F15: Thu
A16: Chi | B16: Nhà cửa | C16: Điện | D16: =IF(C16="","",SUMIFS(GiaoDich!$D:$D,GiaoDich!$C:$C,A16,GiaoDich!$H:$H,C16,GiaoDich!$B:$B,">="&TongQuan!$B$6,GiaoDich!$B:$B,"<"&TongQuan!$B$7)) -> 0 | E16: Thưởng | F16: Thu
A17: Chi | B17: Nhà cửa | C17: Nước | D17: =IF(C17="","",SUMIFS(GiaoDich!$D:$D,GiaoDich!$C:$C,A17,GiaoDich!$H:$H,C17,GiaoDich!$B:$B,">="&TongQuan!$B$6,GiaoDich!$B:$B,"<"&TongQuan!$B$7)) -> 0 | E17: Làm thêm | F17: Thu
... A20: Chi | B20: Nhà cửa | C20: Sửa chữa nhà cửa | D20: =IF(C20="","",SUMIFS(GiaoDich!$D:$D,GiaoDich!$C:$C,A20,GiaoDich!$H:$H,C20,GiaoDich!$B:$B,">="&TongQuan!$B$6,GiaoDich!$B:$B,"<"&TongQuan!$B$7)) -> 0 | E20: Thu khác | F20: Thu
A21: Chi | B21: Nhà cửa | C21: Đồ dùng gia đình | D21: =IF(C21="","",SUMIFS(GiaoDich!$D:$D,GiaoDich!$C:$C,A21,GiaoDich!$H:$H,C21,GiaoDich!$B:$B,">="&TongQuan!$B$6,GiaoDich!$B:$B,"<"&TongQuan!$B$7)) -> 0
A22: Chi | B22: Gia đình | C22: Cho cha mẹ | D22: =IF(C22="","",SUMIFS(GiaoDich!$D:$D,GiaoDich!$C:$C,A22,GiaoDich!$H:$H,C22,GiaoDich!$B:$B,">="&TongQuan!$B$6,GiaoDich!$B:$B,"<"&TongQuan!$B$7)) -> 0
A23: Chi | B23: Gia đình | C23: Con cái | D23: =IF(C23="","",SUMIFS(GiaoDich!$D:$D,GiaoDich!$C:$C,A23,GiaoDich!$H:$H,C23,GiaoDich!$B:$B,">="&TongQuan!$B$6,GiaoDich!$B:$B,"<"&TongQuan!$B$7)) -> 0
A24: Chi | B24: Hiếu hỉ | C24: Biếu tặng | D24: =IF(C24="","",SUMIFS(GiaoDich!$D:$D,GiaoDich!$C:$C,A24,GiaoDich!$H:$H,C24,GiaoDich!$B:$B,">="&TongQuan!$B$6,GiaoDich!$B:$B,"<"&TongQuan!$B$7)) -> 0
A25: Chi | B25: Hiếu hỉ | C25: Cưới hỏi | D25: =IF(C25="","",SUMIFS(GiaoDich!$D:$D,GiaoDich!$C:$C,A25,GiaoDich!$H:$H,C25,GiaoDich!$B:$B,">="&TongQuan!$B$6,GiaoDich!$B:$B,"<"&TongQuan!$B$7)) -> 0
A26: Chi | B26: Hiếu hỉ | C26: Ma chay | D26: =IF(C26="","",SUMIFS(GiaoDich!$D:$D,GiaoDich!$C:$C,A26,GiaoDich!$H:$H,C26,GiaoDich!$B:$B,">="&TongQuan!$B$6,GiaoDich!$B:$B,"<"&TongQuan!$B$7)) -> 0
A27: Chi | B27: Hiếu hỉ | C27: Lì xì | D27: =IF(C27="","",SUMIFS(GiaoDich!$D:$D,GiaoDich!$C:$C,A27,GiaoDich!$H:$H,C27,GiaoDich!$B:$B,">="&TongQuan!$B$6,GiaoDich!$B:$B,"<"&TongQuan!$B$7)) -> 0
A28: Chi | B28: Học tập | C28: Học phí | D28: =IF(C28="","",SUMIFS(GiaoDich!$D:$D,GiaoDich!$C:$C,A28,GiaoDich!$H:$H,C28,GiaoDich!$B:$B,">="&TongQuan!$B$6,GiaoDich!$B:$B,"<"&TongQuan!$B$7)) -> 0
A29: Chi | B29: Học tập | C29: Sách vở, dụng cụ | D29: =IF(C29="","",SUMIFS(GiaoDich!$D:$D,GiaoDich!$C:$C,A29,GiaoDich!$H:$H,C29,GiaoDich!$B:$B,">="&TongQuan!$B$6,GiaoDich!$B:$B,"<"&TongQuan!$B$7)) -> 0
A30: Chi | B30: Học tập | C30: Khóa học | D30: =IF(C30="","",SUMIFS(GiaoDich!$D:$D,GiaoDich!$C:$C,A30,GiaoDich!$H:$H,C30,GiaoDich!$B:$B,">="&TongQuan!$B$6,GiaoDich!$B:$B,"<"&TongQuan!$B$7)) -> 0
A31: Chi | B31: Giải trí | C31: Xem phim, ca nhạc | D31: =IF(C31="","",SUMIFS(GiaoDich!$D:$D,GiaoDich!$C:$C,A31,GiaoDich!$H:$H,C31,GiaoDich!$B:$B,">="&TongQuan!$B$6,GiaoDich!$B:$B,"<"&TongQuan!$B$7)) -> 0
A32: Chi | B32: Giải trí | C32: Game, ứng dụng | D32: =IF(C32="","",SUMIFS(GiaoDich!$D:$D,GiaoDich!$C:$C,A32,GiaoDich!$H:$H,C32,GiaoDich!$B:$B,">="&TongQuan!$B$6,GiaoDich!$B:$B,"<"&TongQuan!$B$7)) -> 0
... A57: Thu | B57: Thu khác | C57: Thu khác | D57: =IF(C57="","",SUMIFS(GiaoDich!$D:$D,GiaoDich!$C:$C,A57,GiaoDich!$H:$H,C57,GiaoDich!$B:$B,">="&TongQuan!$B$6,GiaoDich!$B:$B,"<"&TongQuan!$B$7)) -> 0
D58: =IF(C58="","",SUMIFS(GiaoDich!$D:$D,GiaoDich!$C:$C,A58,GiaoDich!$H:$H,C58,GiaoDich!$B:$B,">="&TongQuan!$B$6,GiaoDich!$B:$B,"<"&TongQuan!$B$7))
D59: =IF(C59="","",SUMIFS(GiaoDich!$D:$D,GiaoDich!$C:$C,A59,GiaoDich!$H:$H,C59,GiaoDich!$B:$B,">="&TongQuan!$B$6,GiaoDich!$B:$B,"<"&TongQuan!$B$7))
D60: =IF(C60="","",SUMIFS(GiaoDich!$D:$D,GiaoDich!$C:$C,A60,GiaoDich!$H:$H,C60,GiaoDich!$B:$B,">="&TongQuan!$B$6,GiaoDich!$B:$B,"<"&TongQuan!$B$7))
D61: =IF(C61="","",SUMIFS(GiaoDich!$D:$D,GiaoDich!$C:$C,A61,GiaoDich!$H:$H,C61,GiaoDich!$B:$B,">="&TongQuan!$B$6,GiaoDich!$B:$B,"<"&TongQuan!$B$7))
D62: =IF(C62="","",SUMIFS(GiaoDich!$D:$D,GiaoDich!$C:$C,A62,GiaoDich!$H:$H,C62,GiaoDich!$B:$B,">="&TongQuan!$B$6,GiaoDich!$B:$B,"<"&TongQuan!$B$7))
D63: =IF(C63="","",SUMIFS(GiaoDich!$D:$D,GiaoDich!$C:$C,A63,GiaoDich!$H:$H,C63,GiaoDich!$B:$B,">="&TongQuan!$B$6,GiaoDich!$B:$B,"<"&TongQuan!$B$7))
D64: =IF(C64="","",SUMIFS(GiaoDich!$D:$D,GiaoDich!$C:$C,A64,GiaoDich!$H:$H,C64,GiaoDich!$B:$B,">="&TongQuan!$B$6,GiaoDich!$B:$B,"<"&TongQuan!$B$7))
D65: =IF(C65="","",SUMIFS(GiaoDich!$D:$D,GiaoDich!$C:$C,A65,GiaoDich!$H:$H,C65,GiaoDich!$B:$B,">="&TongQuan!$B$6,GiaoDich!$B:$B,"<"&TongQuan!$B$7))
D66: =IF(C66="","",SUMIFS(GiaoDich!$D:$D,GiaoDich!$C:$C,A66,GiaoDich!$H:$H,C66,GiaoDich!$B:$B,">="&TongQuan!$B$6,GiaoDich!$B:$B,"<"&TongQuan!$B$7))
...

Sheet HuongDan
A1: HƯỚNG DẪN SỬ DỤNG
A3: 1. Mở sheet TaiKhoan: sửa/thêm tài khoản và nhập số dư đầu kỳ (ô vàng, chữ xanh).
A4: 2. Mở sheet GiaoDich: mỗi giao dịch 1 dòng. Cột Loại, Tài khoản, Hạng mục chọn từ danh sách thả xuống.
A5: 3. Thu / Chi: điền Tài khoản + Hạng mục cha + Hạng mục con. Số tiền luôn nhập số dương.
A6: 4. Chuyển khoản (giữa các tài khoản, kể cả gửi tiết kiệm, rút tiền): điền Tài khoản (đi) và Tài khoản đến. Không tính vào thu/chi.
A7: 5. Điều chỉnh: chỉnh số dư tài khoản cho khớp thực tế (có thể số âm). Không tính vào thu/chi.
A8: 6. Sheet TongQuan: chọn Năm và Tháng ở ô B3, B4. Mọi số liệu tự cập nhật.
A9: 7. Thêm hạng mục mới ở sheet DanhMuc. Tên hạng mục con không được trùng nhau.
A10: Quy ước: ô vàng + chữ xanh = ô để bạn nhập; chữ đen = công thức (đừng sửa); chữ xanh lá = lấy từ sheet khác.
A11: Dòng "Chưa phân loại" ở TongQuan = giao dịch Thu/Chi thiếu Hạng mục cha. Nên bằng 0.
A13: Ví dụ 1 dòng trong GiaoDich:
A14: ID | B14: Ngày | C14: Loại | D14: Số tiền (₫) | E14: Tài khoản | F14: Tài khoản đến | G14: Hạng mục cha | H14: Hạng mục con | I14: Ghi chú
A15: V001 | B15: 46298 | C15: Chi | D15: 35000 | E15: Tiền mặt | G15: Ăn uống | H15: Ăn sáng | I15: Bánh mì + cafe
A16: (Chỉ là ví dụ, không tính vào số liệu. Dữ liệu thật nhập ở sheet GiaoDich.)
